2022-06-30 12:10:54,378 INFO    MainThread:974 [internal.py:wandb_internal():93] W&B internal server running at pid: 974, started at: 2022-06-30 12:10:54.378122
2022-06-30 12:10:54,381 DEBUG   SenderThread:974 [sender.py:send():232] send: header
2022-06-30 12:10:54,381 INFO    WriterThread:974 [datastore.py:open_for_write():75] open: /home/gikok/t0code2/training/wandb/run-20220630_121053-dk2siuad/run-dk2siuad.wandb
2022-06-30 12:10:54,382 DEBUG   SenderThread:974 [sender.py:send():232] send: run
2022-06-30 12:11:23,583 DEBUG   HandlerThread:974 [handler.py:handle_request():141] handle_request: shutdown
2022-06-30 12:11:23,584 INFO    HandlerThread:974 [handler.py:finish():806] shutting down handler
2022-06-30 12:11:24,393 INFO    WriterThread:974 [datastore.py:close():279] close: /home/gikok/t0code2/training/wandb/run-20220630_121053-dk2siuad/run-dk2siuad.wandb
2022-06-30 12:11:28,028 ERROR   SenderThread:974 [retry.py:__call__():126] Retry attempt failed:
Traceback (most recent call last):
  File "/opt/conda/envs/z/lib/python3.7/site-packages/urllib3/connection.py", line 175, in _new_conn
    (self._dns_host, self.port), self.timeout, **extra_kw
  File "/opt/conda/envs/z/lib/python3.7/site-packages/urllib3/util/connection.py", line 95, in create_connection
    raise err
  File "/opt/conda/envs/z/lib/python3.7/site-packages/urllib3/util/connection.py", line 85, in create_connection
    sock.connect(sa)
socket.timeout: timed out

During handling of the above exception, another exception occurred:

Traceback (most recent call last):
  File "/opt/conda/envs/z/lib/python3.7/site-packages/urllib3/connectionpool.py", line 710, in urlopen
    chunked=chunked,
  File "/opt/conda/envs/z/lib/python3.7/site-packages/urllib3/connectionpool.py", line 398, in _make_request
    conn.request(method, url, **httplib_request_kw)
  File "/opt/conda/envs/z/lib/python3.7/site-packages/urllib3/connection.py", line 239, in request
    super(HTTPConnection, self).request(method, url, body=body, headers=headers)
  File "/opt/conda/envs/z/lib/python3.7/http/client.py", line 1281, in request
    self._send_request(method, url, body, headers, encode_chunked)
  File "/opt/conda/envs/z/lib/python3.7/http/client.py", line 1327, in _send_request
    self.endheaders(body, encode_chunked=encode_chunked)
  File "/opt/conda/envs/z/lib/python3.7/http/client.py", line 1276, in endheaders
    self._send_output(message_body, encode_chunked=encode_chunked)
  File "/opt/conda/envs/z/lib/python3.7/http/client.py", line 1036, in _send_output
    self.send(msg)
  File "/opt/conda/envs/z/lib/python3.7/http/client.py", line 976, in send
    self.connect()
  File "/opt/conda/envs/z/lib/python3.7/site-packages/urllib3/connection.py", line 205, in connect
    conn = self._new_conn()
  File "/opt/conda/envs/z/lib/python3.7/site-packages/urllib3/connection.py", line 182, in _new_conn
    % (self.host, self.timeout),
urllib3.exceptions.ConnectTimeoutError: (<urllib3.connection.HTTPConnection object at 0x7f2ba8894250>, 'Connection to 35.204.180.152 timed out. (connect timeout=10)')

During handling of the above exception, another exception occurred:

Traceback (most recent call last):
  File "/opt/conda/envs/z/lib/python3.7/site-packages/requests/adapters.py", line 450, in send
    timeout=timeout
  File "/opt/conda/envs/z/lib/python3.7/site-packages/urllib3/connectionpool.py", line 786, in urlopen
    method, url, error=e, _pool=self, _stacktrace=sys.exc_info()[2]
  File "/opt/conda/envs/z/lib/python3.7/site-packages/urllib3/util/retry.py", line 592, in increment
    raise MaxRetryError(_pool, url, error or ResponseError(cause))
urllib3.exceptions.MaxRetryError: HTTPConnectionPool(host='35.204.180.152', port=8080): Max retries exceeded with url: /graphql (Caused by ConnectTimeoutError(<urllib3.connection.HTTPConnection object at 0x7f2ba8894250>, 'Connection to 35.204.180.152 timed out. (connect timeout=10)'))

During handling of the above exception, another exception occurred:

Traceback (most recent call last):
  File "/opt/conda/envs/z/lib/python3.7/site-packages/wandb/sdk/lib/retry.py", line 102, in __call__
    result = self._call_fn(*args, **kwargs)
  File "/opt/conda/envs/z/lib/python3.7/site-packages/wandb/sdk/internal/internal_api.py", line 140, in execute
    return self.client.execute(*args, **kwargs)
  File "/opt/conda/envs/z/lib/python3.7/site-packages/wandb/vendor/gql-0.2.0/wandb_gql/client.py", line 52, in execute
    result = self._get_result(document, *args, **kwargs)
  File "/opt/conda/envs/z/lib/python3.7/site-packages/wandb/vendor/gql-0.2.0/wandb_gql/client.py", line 60, in _get_result
    return self.transport.execute(document, *args, **kwargs)
  File "/opt/conda/envs/z/lib/python3.7/site-packages/wandb/vendor/gql-0.2.0/wandb_gql/transport/requests.py", line 38, in execute
    request = requests.post(self.url, **post_args)
  File "/opt/conda/envs/z/lib/python3.7/site-packages/requests/api.py", line 117, in post
    return request('post', url, data=data, json=json, **kwargs)
  File "/opt/conda/envs/z/lib/python3.7/site-packages/requests/api.py", line 61, in request
    return session.request(method=method, url=url, **kwargs)
  File "/opt/conda/envs/z/lib/python3.7/site-packages/requests/sessions.py", line 529, in request
    resp = self.send(prep, **send_kwargs)
  File "/opt/conda/envs/z/lib/python3.7/site-packages/requests/sessions.py", line 645, in send
    r = adapter.send(request, **kwargs)
  File "/opt/conda/envs/z/lib/python3.7/site-packages/requests/adapters.py", line 507, in send
    raise ConnectTimeout(e, request=request)
requests.exceptions.ConnectTimeout: HTTPConnectionPool(host='35.204.180.152', port=8080): Max retries exceeded with url: /graphql (Caused by ConnectTimeoutError(<urllib3.connection.HTTPConnection object at 0x7f2ba8894250>, 'Connection to 35.204.180.152 timed out. (connect timeout=10)'))
