2022-06-30 12:39:22,101 INFO    MainThread:25036 [wandb_setup.py:_flush():76] Loading settings from /home/gikok/.config/wandb/settings
2022-06-30 12:39:22,101 INFO    MainThread:25036 [wandb_setup.py:_flush():76] Loading settings from /home/gikok/t0code2/training/wandb/settings
2022-06-30 12:39:22,101 INFO    MainThread:25036 [wandb_setup.py:_flush():76] Loading settings from environment variables: {}
2022-06-30 12:39:22,101 INFO    MainThread:25036 [wandb_setup.py:_flush():76] Inferring run settings from compute environment: {'program': '<python with no main file>'}
2022-06-30 12:39:22,101 INFO    MainThread:25036 [wandb_init.py:_log_setup():428] Logging user logs to /home/gikok/t0code2/training/wandb/run-20220630_123922-1gp3lu9d/logs/debug.log
2022-06-30 12:39:22,101 INFO    MainThread:25036 [wandb_init.py:_log_setup():429] Logging internal logs to /home/gikok/t0code2/training/wandb/run-20220630_123922-1gp3lu9d/logs/debug-internal.log
2022-06-30 12:39:22,101 INFO    MainThread:25036 [wandb_init.py:_jupyter_setup():378] configuring jupyter hooks <wandb.sdk.wandb_init._WandbInit object at 0x7f3e9dbb1f90>
2022-06-30 12:39:22,102 INFO    MainThread:25036 [wandb_init.py:init():462] calling init triggers
2022-06-30 12:39:22,102 INFO    MainThread:25036 [wandb_init.py:init():466] wandb.init called with sweep_config: {}
config: {'dataset_name': 'prompts2opts_001_sub.parquet.gzip', 'model_name_or_path': 'bigscience/T0_3B', 'output_dir': '/home/gikok/output', 'num_train_epochs': 1, 'per_device_train_batch_size': 4, 'per_device_eval_batch_size': 4, 'freeze_encoder': True, 'learning_rate': 10000, 'parallelize': True, 'seed': 42, 'pad_to_max_length': True, 'input_eos': False, 'target_max_length': 64, 'max_length': 128, 'num_warmup_steps': 0, 'debug': False, 'lr_scheduler_type': 'linear', 'num_shots': None, 'weight_decay': 0.1, 'gradient_checkpoint': False, 'gradient_accumulation_steps': 1, 'max_train_steps': None}
2022-06-30 12:39:22,102 INFO    MainThread:25036 [wandb_init.py:init():515] starting backend
2022-06-30 12:39:22,102 INFO    MainThread:25036 [backend.py:_multiprocessing_setup():99] multiprocessing start_methods=fork,spawn,forkserver, using: spawn
2022-06-30 12:39:22,113 INFO    MainThread:25036 [backend.py:ensure_launched():217] starting backend process...
2022-06-30 12:39:22,124 INFO    MainThread:25036 [backend.py:ensure_launched():222] started backend process with pid: 27059
2022-06-30 12:39:22,126 INFO    MainThread:25036 [wandb_init.py:init():525] backend started and connected
2022-06-30 12:39:22,134 INFO    MainThread:25036 [wandb_run.py:_label_probe_notebook():1089] probe notebook
2022-06-30 12:39:22,134 INFO    MainThread:25036 [wandb_run.py:_label_probe_notebook():1099] Unable to probe notebook: 'NoneType' object has no attribute 'get'
2022-06-30 12:39:22,134 INFO    MainThread:25036 [wandb_init.py:init():596] updated telemetry
2022-06-30 12:39:22,151 INFO    MainThread:25036 [wandb_init.py:init():628] communicating run to backend with 30 second timeout
2022-06-30 12:39:50,301 ERROR   Thread-4  :25036 [retry.py:__call__():126] Retry attempt failed:
Traceback (most recent call last):
  File "/opt/conda/envs/z/lib/python3.7/site-packages/urllib3/connection.py", line 175, in _new_conn
    (self._dns_host, self.port), self.timeout, **extra_kw
  File "/opt/conda/envs/z/lib/python3.7/site-packages/urllib3/util/connection.py", line 95, in create_connection
    raise err
  File "/opt/conda/envs/z/lib/python3.7/site-packages/urllib3/util/connection.py", line 85, in create_connection
    sock.connect(sa)
socket.timeout: timed out

During handling of the above exception, another exception occurred:

Traceback (most recent call last):
  File "/opt/conda/envs/z/lib/python3.7/site-packages/urllib3/connectionpool.py", line 710, in urlopen
    chunked=chunked,
  File "/opt/conda/envs/z/lib/python3.7/site-packages/urllib3/connectionpool.py", line 398, in _make_request
    conn.request(method, url, **httplib_request_kw)
  File "/opt/conda/envs/z/lib/python3.7/site-packages/urllib3/connection.py", line 239, in request
    super(HTTPConnection, self).request(method, url, body=body, headers=headers)
  File "/opt/conda/envs/z/lib/python3.7/http/client.py", line 1281, in request
    self._send_request(method, url, body, headers, encode_chunked)
  File "/opt/conda/envs/z/lib/python3.7/http/client.py", line 1327, in _send_request
    self.endheaders(body, encode_chunked=encode_chunked)
  File "/opt/conda/envs/z/lib/python3.7/http/client.py", line 1276, in endheaders
    self._send_output(message_body, encode_chunked=encode_chunked)
  File "/opt/conda/envs/z/lib/python3.7/http/client.py", line 1036, in _send_output
    self.send(msg)
  File "/opt/conda/envs/z/lib/python3.7/http/client.py", line 976, in send
    self.connect()
  File "/opt/conda/envs/z/lib/python3.7/site-packages/urllib3/connection.py", line 205, in connect
    conn = self._new_conn()
  File "/opt/conda/envs/z/lib/python3.7/site-packages/urllib3/connection.py", line 182, in _new_conn
    % (self.host, self.timeout),
urllib3.exceptions.ConnectTimeoutError: (<urllib3.connection.HTTPConnection object at 0x7f3f9fa840d0>, 'Connection to 35.204.180.152 timed out. (connect timeout=10)')

During handling of the above exception, another exception occurred:

Traceback (most recent call last):
  File "/opt/conda/envs/z/lib/python3.7/site-packages/requests/adapters.py", line 450, in send
    timeout=timeout
  File "/opt/conda/envs/z/lib/python3.7/site-packages/urllib3/connectionpool.py", line 786, in urlopen
    method, url, error=e, _pool=self, _stacktrace=sys.exc_info()[2]
  File "/opt/conda/envs/z/lib/python3.7/site-packages/urllib3/util/retry.py", line 592, in increment
    raise MaxRetryError(_pool, url, error or ResponseError(cause))
urllib3.exceptions.MaxRetryError: HTTPConnectionPool(host='35.204.180.152', port=8081): Max retries exceeded with url: /graphql (Caused by ConnectTimeoutError(<urllib3.connection.HTTPConnection object at 0x7f3f9fa840d0>, 'Connection to 35.204.180.152 timed out. (connect timeout=10)'))

During handling of the above exception, another exception occurred:

Traceback (most recent call last):
  File "/opt/conda/envs/z/lib/python3.7/site-packages/wandb/sdk/lib/retry.py", line 102, in __call__
    result = self._call_fn(*args, **kwargs)
  File "/opt/conda/envs/z/lib/python3.7/site-packages/wandb/sdk/internal/internal_api.py", line 140, in execute
    return self.client.execute(*args, **kwargs)
  File "/opt/conda/envs/z/lib/python3.7/site-packages/wandb/vendor/gql-0.2.0/wandb_gql/client.py", line 52, in execute
    result = self._get_result(document, *args, **kwargs)
  File "/opt/conda/envs/z/lib/python3.7/site-packages/wandb/vendor/gql-0.2.0/wandb_gql/client.py", line 60, in _get_result
    return self.transport.execute(document, *args, **kwargs)
  File "/opt/conda/envs/z/lib/python3.7/site-packages/wandb/vendor/gql-0.2.0/wandb_gql/transport/requests.py", line 38, in execute
    request = requests.post(self.url, **post_args)
  File "/opt/conda/envs/z/lib/python3.7/site-packages/requests/api.py", line 117, in post
    return request('post', url, data=data, json=json, **kwargs)
  File "/opt/conda/envs/z/lib/python3.7/site-packages/requests/api.py", line 61, in request
    return session.request(method=method, url=url, **kwargs)
  File "/opt/conda/envs/z/lib/python3.7/site-packages/requests/sessions.py", line 529, in request
    resp = self.send(prep, **send_kwargs)
  File "/opt/conda/envs/z/lib/python3.7/site-packages/requests/sessions.py", line 645, in send
    r = adapter.send(request, **kwargs)
  File "/opt/conda/envs/z/lib/python3.7/site-packages/requests/adapters.py", line 507, in send
    raise ConnectTimeout(e, request=request)
requests.exceptions.ConnectTimeout: HTTPConnectionPool(host='35.204.180.152', port=8081): Max retries exceeded with url: /graphql (Caused by ConnectTimeoutError(<urllib3.connection.HTTPConnection object at 0x7f3f9fa840d0>, 'Connection to 35.204.180.152 timed out. (connect timeout=10)'))
2022-06-30 12:39:52,152 INFO    MainThread:25036 [interface_shared.py:_communicate_run():326] couldn't get run from backend
2022-06-30 12:39:52,153 ERROR   MainThread:25036 [wandb_init.py:init():636] backend process timed out
2022-06-30 12:39:52,153 ERROR   MainThread:25036 [wandb_init.py:init():647] encountered error: Error communicating with wandb process
try: wandb.init(settings=wandb.Settings(start_method='fork'))
or:  wandb.init(settings=wandb.Settings(start_method='thread'))
For more info see: https://docs.wandb.ai/library/init#init-start-error
2022-06-30 12:45:11,634 WARNING MainThread:25036 [wandb_init.py:init():1020] interrupted
Traceback (most recent call last):
  File "/opt/conda/envs/z/lib/python3.7/site-packages/wandb/sdk/wandb_init.py", line 999, in init
    run = wi.init()
  File "/opt/conda/envs/z/lib/python3.7/site-packages/wandb/sdk/wandb_init.py", line 651, in init
    backend.cleanup()
  File "/opt/conda/envs/z/lib/python3.7/site-packages/wandb/sdk/backend/backend.py", line 248, in cleanup
    self.wandb_process.join()
  File "/opt/conda/envs/z/lib/python3.7/multiprocessing/process.py", line 140, in join
    res = self._popen.wait(timeout)
  File "/opt/conda/envs/z/lib/python3.7/multiprocessing/popen_fork.py", line 48, in wait
    return self.poll(os.WNOHANG if timeout == 0.0 else 0)
  File "/opt/conda/envs/z/lib/python3.7/multiprocessing/popen_fork.py", line 28, in poll
    pid, sts = os.waitpid(self.pid, flag)
KeyboardInterrupt
